INFO:root:[{"account":"Cash","amount":"5.0"},{"account":"Cash","amount":"5.0"},{"account":"Cash","amount":"5.0"},{"account":"Cash","amount":"5.0"},{"account":"Cash","amount":"8.0"},{"account":"Cash","amount":"9.0"},{"account":"Cash","amount":"10.0"},{"account":"Cash","amount":"-10.0"},{"account":"Bank","amount":"-20.0"},{"account":"Cash","amount":"-10.0"}]
INFO:root:[]
INFO:root:[]
INFO:root:[]
INFO:root:[{"account":"Cash","amount":"1000"},{"account":"Cash","amount":"-1000"}]
INFO:root:[{"account":"Cash","amount":"1000.0"},{"account":"Cash","amount":"-1000.0"}]
INFO:root:[{"account":"Cash","amount":"1000.0"},{"account":"Cash","amount":"-1000.0"}]
INFO:root:[{"account":"Cash","amount":"1000"},{"account":"Cash","amount":"-1000.0"}]
INFO:root:[{"account":"Cash","amount":"150"},{"account":"Cash","amount":"-150"}]
INFO:root:[{"account":"Cash","amount":"150"},{"account":"Cash","amount":"-150.0"}]
INFO:root:[{"account":"Cash","amount":"10"},{"account":"Bank","amount":"-10"}]
INFO:root:[{"account":"Bank","amount":"100"},{"account":"Debtors","amount":"100"},{"account":"Purchases","amount":"-150"},{"account":"Cash","amount":"-50"}]
INFO:root:[{"account":"Bank","amount":"100.0"},{"account":"Debtors","amount":"100.0"},{"account":"Purchases","amount":"-150.0"},{"account":"Cash","amount":"-50.0"},{"account":"Cash","amount":"50"},{"account":"Cash","amount":"-50"}]
INFO:root:[{"account":"Cash","amount":"-1000.0"},{"account":"Bank","amount":"500"},{"account":"Capital","amount":"500"}]
ERROR:asyncio:Exception in callback _ProactorBasePipeTransport._call_connection_lost(None)
handle: <Handle _ProactorBasePipeTransport._call_connection_lost(None)>
Traceback (most recent call last):
  File "C:\Python39\lib\asyncio\events.py", line 80, in _run
    self._context.run(self._callback, *self._args)
  File "C:\Python39\lib\asyncio\proactor_events.py", line 162, in _call_connection_lost
    self._sock.shutdown(socket.SHUT_RDWR)
ConnectionResetError: [WinError 10054] Se ha forzado la interrupción de una conexión existente por el host remoto
INFO:root:[{"account":"Bank","amount":"650"},{"account":"Cash","amount":"100.0"},{"account":"Capital","amount":"-650.0"},{"account":"Debtors","amount":"-100.0"}]
INFO:root:[{"account":"Bank","amount":"650.0"},{"account":"Cash","amount":"100.0"},{"account":"Capital","amount":"-650.0"},{"account":"Debtors","amount":"-100.0"}]
INFO:root:[{"account":"Bank","amount":"650.0"},{"account":"Cash","amount":"100.0"},{"account":"Capital","amount":"-650.0"},{"account":"Debtors","amount":"-100.0"}]
INFO:root:[{"account":"Bank","amount":"650.0"},{"account":"Cash","amount":"100.0"},{"account":"Capital","amount":"-650.0"},{"account":"Debtors","amount":"-100.0"}]
INFO:root:[{"account":"Bank","amount":"650.0"},{"account":"Cash","amount":"100.0"},{"account":"Capital","amount":"-650.0"},{"account":"Debtors","amount":"-100.0"}]
INFO:root:[{"account":"Bank","amount":"100.0"},{"account":"Cash","amount":"-100.0"}]
INFO:root:[{"account":"Bank","amount":"100.0"},{"account":"Cash","amount":"-100.0"}]
INFO:root:[{"account":"Cash","amount":"100"},{"account":"Bank","amount":"-100"}]
INFO:root:[{"account":"Cash","amount":"100.0"},{"account":"Bank","amount":"-100.0"},{"account":"Debtors","amount":"50"},{"account":"Capital","amount":"-50"}]
ERROR:asyncio:Exception in callback _ProactorBasePipeTransport._call_connection_lost(None)
handle: <Handle _ProactorBasePipeTransport._call_connection_lost(None)>
Traceback (most recent call last):
  File "C:\Python39\lib\asyncio\events.py", line 80, in _run
    self._context.run(self._callback, *self._args)
  File "C:\Python39\lib\asyncio\proactor_events.py", line 162, in _call_connection_lost
    self._sock.shutdown(socket.SHUT_RDWR)
ConnectionResetError: [WinError 10054] Se ha forzado la interrupción de una conexión existente por el host remoto
ERROR:asyncio:Exception in callback _ProactorBasePipeTransport._call_connection_lost(None)
handle: <Handle _ProactorBasePipeTransport._call_connection_lost(None)>
Traceback (most recent call last):
  File "C:\Python39\lib\asyncio\events.py", line 80, in _run
    self._context.run(self._callback, *self._args)
  File "C:\Python39\lib\asyncio\proactor_events.py", line 162, in _call_connection_lost
    self._sock.shutdown(socket.SHUT_RDWR)
ConnectionResetError: [WinError 10054] Se ha forzado la interrupción de una conexión existente por el host remoto
ERROR:asyncio:Exception in callback _ProactorBasePipeTransport._call_connection_lost(None)
handle: <Handle _ProactorBasePipeTransport._call_connection_lost(None)>
Traceback (most recent call last):
  File "C:\Python39\lib\asyncio\events.py", line 80, in _run
    self._context.run(self._callback, *self._args)
  File "C:\Python39\lib\asyncio\proactor_events.py", line 162, in _call_connection_lost
    self._sock.shutdown(socket.SHUT_RDWR)
ConnectionResetError: [WinError 10054] Se ha forzado la interrupción de una conexión existente por el host remoto
ERROR:asyncio:Exception in callback _ProactorBasePipeTransport._call_connection_lost(None)
handle: <Handle _ProactorBasePipeTransport._call_connection_lost(None)>
Traceback (most recent call last):
  File "C:\Python39\lib\asyncio\events.py", line 80, in _run
    self._context.run(self._callback, *self._args)
  File "C:\Python39\lib\asyncio\proactor_events.py", line 162, in _call_connection_lost
    self._sock.shutdown(socket.SHUT_RDWR)
ConnectionResetError: [WinError 10054] Se ha forzado la interrupción de una conexión existente por el host remoto
ERROR:asyncio:Exception in callback _ProactorBasePipeTransport._call_connection_lost(None)
handle: <Handle _ProactorBasePipeTransport._call_connection_lost(None)>
Traceback (most recent call last):
  File "C:\Python39\lib\asyncio\events.py", line 80, in _run
    self._context.run(self._callback, *self._args)
  File "C:\Python39\lib\asyncio\proactor_events.py", line 162, in _call_connection_lost
    self._sock.shutdown(socket.SHUT_RDWR)
ConnectionResetError: [WinError 10054] Se ha forzado la interrupción de una conexión existente por el host remoto
ERROR:asyncio:Exception in callback _ProactorBasePipeTransport._call_connection_lost(None)
handle: <Handle _ProactorBasePipeTransport._call_connection_lost(None)>
Traceback (most recent call last):
  File "C:\Python39\lib\asyncio\events.py", line 80, in _run
    self._context.run(self._callback, *self._args)
  File "C:\Python39\lib\asyncio\proactor_events.py", line 162, in _call_connection_lost
    self._sock.shutdown(socket.SHUT_RDWR)
ConnectionResetError: [WinError 10054] Se ha forzado la interrupción de una conexión existente por el host remoto
ERROR:asyncio:Exception in callback _ProactorBasePipeTransport._call_connection_lost(None)
handle: <Handle _ProactorBasePipeTransport._call_connection_lost(None)>
Traceback (most recent call last):
  File "C:\Python39\lib\asyncio\events.py", line 80, in _run
    self._context.run(self._callback, *self._args)
  File "C:\Python39\lib\asyncio\proactor_events.py", line 162, in _call_connection_lost
    self._sock.shutdown(socket.SHUT_RDWR)
ConnectionResetError: [WinError 10054] Se ha forzado la interrupción de una conexión existente por el host remoto
INFO:root:[{"account":"Bank","amount":"100.0"},{"account":"Cash","amount":"-100.0"},{"account":"VAT","amount":"400"},{"account":"Other income","amount":"-400"}]
INFO:root:[{"account":"Other income","amount":"-500"},{"account":"Cash","amount":"100"},{"account":"VAT","amount":"400"}]
INFO:root:[{"account":"Cash","amount":"100.0"},{"account":"VAT","amount":"400.0"},{"account":"Other income","amount":"-500.0"}]
INFO:root:[{"account":"other debtors","amount":"100.0"},{"account":"VAT","amount":"400.0"},{"account":"Other income","amount":"-500.0"}]
INFO:root:[{"account":"other debtors","amount":"100.0"},{"account":"Bank","amount":"400.0"},{"account":"Other income","amount":"-500.0"}]
INFO:root:[{"account":"Rent","amount":"400"},{"account":"VAT","amount":"100"},{"account":"Debtors","amount":"-500.0"}]
